Workbook

Sheet data
A1: =Victory!AC131 | B1: =Victory!AD131 | C1: =Victory!AE131 | D1: =AVERAGE(A1:C1) -> #DIV/0! | E1: Total | F1: =MID(SUM(A$1:C$1),1,1) -> 0 | G1: =IF(LEN(SUM(A$1:C$1))>1,MID(SUM(A$1:C$1),2,1),0) -> 0 | H1: =SUM(F1+G1) -> 0 | I1: =MID(D5,1,1) -> - | K1: =mid(D5,2,1) -> 1 | L1: =mid(C5,2,1)-1 -> -1 | N1: =mid(D4,2,1) | O1: =mid(D4,1,1)*mid(C4,2,1) -> 0 | P1: =mid(C4,1,1) | S1: 328 | U1: F | W1: S | AC1: L
C2: 3
C3: 1 | D3: ='Copy of data'!E2 -> 4096
A4: =MID(D6,1,1) -> 1 | B4: =mid(D6,2,1) | C4: =CONCAT(A1,B1) | D4: =CONCATENATE(C3,B1) -> 1 | E4: =C4-D4 -> -1 | F4: =H1 -> 0 | G4: =G1 -> 0 | H4: =F1 -> 0 | I4: =mid(D6,1,1) -> 1 | K4: =mid(D6,2,1) | L4: =mid(D7,1,1) + mid(D7,2,1) -> 0 | N4: =F7 -> -1 | O4: =H7-G7 -> 1 | P4: =G7 | T4: F | U4: =I7 | W4: =CONCAT($U4,W$3) | X4: =CONCAT($U4,X$3) | Y4: =CONCAT($U4,Y$3) | Z4: =CONCAT($U4,Z$3) | AA4: =CONCAT($U4,AA$3) | AB4: =CONCAT($U4,AB$3)
B5: 0 | C5: =H1-C4 -> 0 | D5: =H1-D4 -> -1 | E5: =C5+D5 -> -1 | F5: =F1 -> 0 | G5: =H1 -> 0 | H5: =G1 -> 0 | I5: =mid(C6,2,1) | K5: =mid(C6,1,1)-1 -> -1 | L5: =mid(C7,1,1)
C6: =C4+H1 -> 0 | D6: =D4+H1 -> 1 | E6: =C6+D6 -> 1 | F6: =A1 | G6: =C3 -> 1 | H6: =B1-3 -> -3 | I6: =mid(C7,2,1) | K6: =mid(C7,2,1)-mid(C6,2,1) -> 0 | L6: =mid(C6,1,1)+mid(C6, 2,1) -> 0
A7: =MID(C6,1,1) -> 0 | B7: 0 | C7: =mid(D4,3,1) | D7: =MID(D4,2,1) | E7: KARUNYA PLUS - sometime matches the result, otherwise take values from here and down think about add 3 and divide 3 last two digits | F7: =CONCATENATE(MID(C4,1,1))-1 -> -1 | G7: =B1 | H7: =C3 -> 1 | I7: =MID(H8,2,1) | J7: =I7 | K7: =MID(H8,1,1)+2 -> 2 | L7: =H7-2 -> -1 | N7: =L8 -> -2 | O7: =L8*K8 -> -4 | P7: =I8-L8 -> 3 | U7: PICK
A8: =MID(C6,3,1) | B8: =D18 -> 1 | C8: =mid(D4,1,1) -> 1 | D8: 0 | E8: sometime +1, -1 on first and last digit, +2, -2 on two digits | F8: =CONCATENATE(MID(C5,1,1))+1 -> 1 | G8: =CONCATENATE(MID(C4,2,1))*MID(D4,1,1) -> 0 | H8: =CONCATENATE(MID(C4,2,1))*MID(C4,2,1) -> 0 | I8: =H7 -> 1 | J8: =mid(H7,1,1)-1 -> 0 | K8: =mid(H8,1,1)+2 -> 2 | L8: =mid(H8,2,1)-2 -> -2 | N8: =IF(I8=5,8,I8) -> 1 | O8: =K8+1 -> 3 | P8: =L8-1 -> -3 | Q8: if values is 0 consider as 9 | AA8: =123*13 -> 1599
A9: =H1 -> 0 | B9: =G7 | C9: =2 -> 2 | D9: =C3+1 -> 2 | E9: =B1+1 -> 1 | F9: =B20 | G9: =B22 | H9: =B21 | I9: =Mid(H8,1,1)+1 -> 1 | J9: =mid(H8,1,1) -> 0 | K9: =MID(H8,2,1)+2 -> 2 | L9: =H7 -> 1 | N9: =O8/2 -> 1.5 | O9: =N8-P8 -> 4 | P9: =O9-P8 -> 7 | AA9: 25 | AB9: 26
C10: =A1*B1 -> 0 | D10: =B1*C3 -> 0 | F10: =F9+H9 -> 0 | G10: =CONCATENATE(MID(E48,2,1)) -> 7 | H10: =CONCATENATE(MID(E48,3,1)) -> 2 | I10: =MID(H8,1,1)+2 -> 2 | K10: =MID(H8, 2,1)-1 -> -1 | L10: =H7 -> 1 | N10: =I10*2 -> 4 | O10: =N10-K10 -> 5 | P10: =O10+L10 -> 6 | AA10: 123 | AB10: 33
B11: 8 become 5 | C11: =B1+C0 -> #ERROR! | D11: =C11*A1 -> #ERROR! | E11: =CONCATENATE(left(E4,3), right(E5,2)) -> -1-1 | F11: =F9+G9 -> 0 | I11: =MID(H8,2,1) | K11: =MID(H8,1,1)-1 -> -1 | L11: =G8-1 -> -1 | N11: =N8+2 -> 3 | O11: =O8+2 -> 5 | P11: =N9 -> 1.5 | Y11: =AA9+AB9 -> 51 | Z11: =Y11*30 -> 1530
C12: =A1*B1 -> 0 | D12: =B1+C3 -> 1 | F12: =G9+H9 -> 0 | I12: =MID(H8,1,1)*2 -> 0 | J12: =I12-1 -> -1 | K12: =mid(H8,2,1)/3 -> 0 | L12: =MID(H8,2,1)-H7 -> -1 | N12: =N11-1 -> 2 | O12: =O11-1 -> 4 | P12: =P11-1 -> 0.5 | Y12: =AA10+AB10 -> 156 | Z12: =Y12*13 -> 2028
B13: 0 become 9 | C13: =C3 -> 1 | D13: =B1-1 -> -1 | E13: =A1 | I13: =mid(C6,2,1) | J13: =I13-1 -> -1 | K13: =mid(C7,1,1)-C8 -> -1 | L13: =mid(C7,1,1) | N13: =N12-1 -> 1 | O13: =O12-1 -> 3 | P13: =P12+1 -> 1.5
A14: reference | B14: result | C14: =D9-1 -> 1 | D14: =D9+C9 -> 4 | E14: =E9 -> 1 | I14: =mid(C6,1,1) -> 0 | J14: =I14-1 -> -1 | K14: =mid(D7,1,1) | L14: =mid(D7,2,1) | N14: =I8-2 -> -1 | O14: =K8 -> 2 | P14: =L8*2 -> -4 | Y14: =5150 -> 5150
B15: 107 | C15: =D13 -> -1 | D15: =D13+E13 -> -1 | E15: =E14-1 -> 0 | I15: =mid(D4,1,1)+mid(D4, 2,1) -> 1 | K15: =mid(C4,2,1) | L15: =mid(C6,1,1) -> 0 | N15: =MID(H8,1,1)+1 -> 1 | O15: =MID(H8,2,1)+1 -> 1 | P15: =O15+H7 -> 2 | Y15: =Y14-SUM(Z11:Z12) -> 1592
A16: Matches exactly, sometime middle in the other places | B16: =CONCATENATE(A7,A9,B4) -> 00 | F16: =MID(C6,1,1) -> 0 | G16: =MID(C4,2,1)-mid(D4,1,1) -> -1 | H16: =MID(D4,2,1) | I16: =mid(G8,2,1) | K16: =MID(G8,1,1)-1 -> -1 | L16: =mid(C4,1,1) | N16: =MID(L11,1,1) -> - | O16: =MID(L11,2,1)+3 -> 4 | P16: =L12*3 -> -3
A17: =Victory!AC125 | B17: =Victory!AC136 -> 3 | C17: =E13 | D17: =D13 -> -1 | E17: =D14+1 -> 5 | F17: =MID(I17,1,1) | G17: =MID(I17,2,1) | H17: =MID(I17,3,1) | I17: =MID(G8,2,1) | K17: =MID(G8,1,1)-1 -> -1 | L17: =G7 | N17: =O12 -> 4 | O17: =if(O11=8,5,O11) -> 5 | P17: =O13 -> 3
A18: =Victory!AC124 | C18: =C17 | D18: =C17-D17 -> 1 | E18: =E17 -> 5 | F18: =MID(C4,1,1)+1 -> 1 | G18: =mid(C4,2,1) + mid(D4,1,1) -> 1 | H18: =mid(D4,2,1)-1 -> -1 | I18: =mid(D6,3,1) | L18: =mid(D7,2,1)
A19: =ABs(A17-B17) -> 3 | C19: =D6 -> 1 | D19: =LEFT(C6,2) -> 0 | I19: =I17/2 -> 0 | K19: =K11 -> -1 | L19: =L17+1 -> 1
A20: =abs(A18-B17) -> 3 | C20: =concatenate(right(D18, 1), left(D18,1)) -> 11 | I20: =I10 -> 2 | K20: =I11 | L20: =I12-1 -> -1 | S20: =O20+P20 -> 0 | T20: =Q20 | U20: =P20
A21: =A19+A20 -> 6 | F21: =G18 -> 1 | G21: =F18 -> 1 | H21: =H18 -> -1 | I21: =MID(H8,1,1)+MID(H8,2,1) -> 0 | L21: =H7 -> 1
A22: =A20*A19 -> 9 | E22: check this for last digit - winwin / FF first digit | F22: =I6 | G22: =K6+1 -> 1 | H22: =L6-1 -> -1
F23: =I5-1 -> -1 | G23: =K5-1 -> -2 | H23: =L5
E24: check this option for middle digit | G24: =K1-1 -> 0 | H24: =H23/F26 -> 0
A25: 1. prevous result last 2 digit, support digit | F25: =I6+1 -> 1 | G25: =F25+K6 -> 1 | H25: =K6+L6 -> 0 | I25: Pefect match - just replace 20 as 00 is | K25: =CONCATENATE(mid(I35,1,1),mid(I35,2,1),mid(I35,3,1)-2) -> -2-2
A26: 1. prevous result last 2 digit, A17, A18 | F26: =F23-D37 -> -1 | G26: =K10 -> -1 | H26: =0 -> 0 | K26: =CONCATENATE(mid(I35,1,1),mid(I35,2,1),mid(I35,3,1)/2) -> -20
F27: =H25-1 -> -1 | G27: =G25 -> 1 | H27: =H25+G25 -> 1 | I27: 214 become 294 | P27: 503
A28: =Victory!AC129 | D28: =sqft(629) -> #NAME? | E28: somthing to check | F28: =0 -> 0 | G28: =G27 -> 1 | H28: =F27-1 -> -2 | I28: BT check | K28: =CONCATENATE(A1+1,B1+1,C3+1) -> 112 | L28: =Concatenate(MID(K28,4,1)-MID(K28,3,1),MID(K28,2,1),MID(K28,1,1)) -> -211 | P28: 793 | T28: 69 | U28: 96 | V28: 960
A29: =Victory!AD129 | E29: check this color for first digit or last digit | F29: =F22 | H29: =G22 -> 1 | K29: sometime reverse, -1 added as 1 with all numbers - KN PLUS - first two digit match Sometime, Middle digit matches | O29: 541 | P29: 229 | T29: 963 | U29: 369 | V29: 769
A30: =A28*A29 -> 0 | F30: =C30-B1 -> 0 | G30: =F30+1 -> 1 | H30: =D30
A31: =A28*left(A29, 1) -> 0 | E31: check this color for first digit or last digit | F31: =#REF! -> #REF! | G31: =G26-1 -> -2 | H31: =H26+2 -> 2 | I31: become 002 - also matches first and last digit | K31: =CONCATENATE(mid(I35,1,1),mid(I35,2,1),mid(I35,3,1)+2) -> -22 | P31: 519 | T31: 967 | U31: 69
A32: =A28*right(A29, 1) -> 0 | E32: check this color for first digit or last digit | F32: =C27+2 -> 2 | G32: =D27+2 -> 2 | H32: =E27+1 -> 1 | K32: =CONCATENATE(mid(I35,3,1)+2,mid(I35,2,1),mid(I35,1,1)) -> 22-
A33: =A28*(A29+1) -> 0 | E33: =CONCATENATE(B33+MID(C33,1,1),MID(C33,2,1)) -> 0 | F33: =N10-1 -> 3 | G33: =F33+1 -> 4 | H33: =P10 -> 6 | M33: =T10
A34: =A28*(A29+2) -> 0 | B34: =concatenate(right(A34,1), left(A34,1)) -> 00 | E34: - 1 or +1 or 1, 2 or 2, 1 or 2, 3 or 3,2 on these digits, 1, 3 | F34: =F23-1 -> -2 | G34: =G23 -> -2 | H34: =H23 | I34: =CONCATENATE(F34,G34,H34) -> -2-2 | K34: Sometime matches AS IS - firstime
A35: =A28*(A29-1) -> 0 | E35: SK - 226 - multiply by 3, 2, divide by 2,3 | F35: =G23 -> -2 | G35: =F28 -> 0 | H35: =G24 -> 0 | I35: =CONCATENATE(F35,G35,H35) -> -200 | K35: Check this - drop 1 from first /last
A36: =A28*(A29-2) -> 0 | B36: =LEFT(A36,2) -> 0 | I36: =CONCATENATE(F36,G36,H36) | K36: 343, 041 = 400 (433-033) | O36: 813
E37: +,-,- | F37: =2 -> 2 | G37: =F25+1 -> 2 | H37: =G25+1 -> 2 | K37: BACKWARD - THINK ABOUT - VALUE | L37: =54-12 -> 42 | O37: 904
F38: =E26 | G38: =E25 | H38: =E24 -> check this option for middle digit | I38: =CONCATENATE(F38,G38,H38) -> check this option for middle digit | K38: backward - THINK ABOUT - VALUE
F39: =H38 -> check this option for middle digit | G39: =G38 | H39: =F38 | I39: =CONCATENATE(F39,G39,H39) -> check this option for middle digit
F40: =F39 -> check this option for middle digit | G40: =F40-G39 -> #VALUE! | H40: =H39-H39 -> 0
...

Sheet Copy of data 1
A1: =data!C1 | B1: =data!B1 | C1: =data!A1 | D1: =AVERAGE(A1:C1) -> #DIV/0! | E1: Total | F1: =MID(SUM(A$1:C$1),1,1) -> 0 | G1: =IF(LEN(SUM(A$1:C$1))>1,MID(SUM(A$1:C$1),2,1),0) -> 0 | H1: =SUM(F1+G1) -> 0 | I1: =MID(D5,1,1) -> - | K1: =mid(D5,2,1) -> 1 | L1: =mid(C5,2,1)-1 -> -1 | N1: =mid(D4,2,1) | O1: =mid(D4,1,1)*mid(C4,2,1) -> 0 | P1: =mid(C4,1,1) | S1: 328 | U1: F | W1: S | AC1: L
C2: 3
C3: 1 | D3: ='Copy of data'!E2 -> 4096
A4: =MID(D6,1,1) -> 1 | B4: =mid(D6,2,1) | C4: =CONCAT(A1,B1) | D4: =CONCATENATE(C3,B1) -> 1 | E4: =C4-D4 -> -1 | F4: =H1 -> 0 | G4: =G1 -> 0 | H4: =F1 -> 0 | I4: =mid(D6,1,1) -> 1 | K4: =mid(D6,2,1) | L4: =mid(D7,1,1) + mid(D7,2,1) -> 0 | N4: =F7 -> -1 | O4: =H7-G7 -> 1 | P4: =G7 | T4: F | U4: =I7 | W4: =CONCAT($U4,W$3) | X4: =CONCAT($U4,X$3) | Y4: =CONCAT($U4,Y$3) | Z4: =CONCAT($U4,Z$3) | AA4: =CONCAT($U4,AA$3) | AB4: =CONCAT($U4,AB$3)
B5: 0 | C5: =H1-C4 -> 0 | D5: =H1-D4 -> -1 | E5: =C5+D5 -> -1 | F5: =F1 -> 0 | G5: =H1 -> 0 | H5: =G1 -> 0 | I5: =mid(C6,2,1) | K5: =mid(C6,1,1)-1 -> -1 | L5: =mid(C7,1,1)
C6: =C4+H1 -> 0 | D6: =D4+H1 -> 1 | E6: =C6+D6 -> 1 | F6: =A1 | G6: =C3 -> 1 | H6: =B1-3 -> -3 | I6: =mid(C7,2,1) | K6: =mid(C7,2,1)-mid(C6,2,1) -> 0 | L6: =mid(C6,1,1)+mid(C6, 2,1) -> 0
A7: =MID(C6,1,1) -> 0 | B7: 0 | C7: =mid(D4,3,1) | D7: =MID(D4,2,1) | E7: KARUNYA PLUS - sometime matches the result, otherwise take values from here and down think about add 3 and divide 3 last two digits | F7: =CONCATENATE(MID(C4,1,1))-1 -> -1 | G7: =B1 | H7: =C3 -> 1 | I7: =MID(H8,2,1) | J7: =I7 | K7: =MID(H8,1,1)+2 -> 2 | L7: =H7-2 -> -1 | N7: =L8 -> -2 | O7: =L8*K8 -> -4 | P7: =I8-L8 -> 3 | U7: PICK
A8: =MID(C6,3,1) | B8: =D18 -> 1 | C8: =mid(D4,1,1) -> 1 | D8: 0 | E8: sometime +1, -1 on first and last digit, +2, -2 on two digits | F8: =CONCATENATE(MID(C5,1,1))+1 -> 1 | G8: =CONCATENATE(MID(C4,2,1))*MID(D4,1,1) -> 0 | H8: =CONCATENATE(MID(C4,2,1))*MID(C4,2,1) -> 0 | I8: =H7 -> 1 | J8: =mid(H7,1,1)-1 -> 0 | K8: =mid(H8,1,1)+2 -> 2 | L8: =mid(H8,2,1)-2 -> -2 | N8: =IF(I8=5,8,I8) -> 1 | O8: =K8+1 -> 3 | P8: =L8-1 -> -3 | Q8: if values is 0 consider as 9 | AA8: =123*13 -> 1599
A9: =H1 -> 0 | B9: =G7 | C9: =2 -> 2 | D9: =C3+1 -> 2 | E9: =B1+1 -> 1 | F9: =B20 | G9: =B22 | H9: =B21 | I9: =Mid(H8,1,1)+1 -> 1 | J9: =mid(H8,1,1) -> 0 | K9: =MID(H8,2,1)+2 -> 2 | L9: =H7 -> 1 | N9: =O8/2 -> 1.5 | O9: =N8-P8 -> 4 | P9: =O9-P8 -> 7 | AA9: 25 | AB9: 26
C10: =A1*B1 -> 0 | D10: =B1*C3 -> 0 | F10: =F9+H9 -> 0 | G10: =CONCATENATE(MID(E48,2,1)) -> 7 | H10: =CONCATENATE(MID(E48,3,1)) -> 2 | I10: =MID(H8,1,1)+2 -> 2 | K10: =MID(H8, 2,1)-1 -> -1 | L10: =H7 -> 1 | N10: =I10*2 -> 4 | O10: =N10-K10 -> 5 | P10: =O10+L10 -> 6 | AA10: 123 | AB10: 33
B11: 8 become 5 | C11: =B1+C0 -> #ERROR! | D11: =C11*A1 -> #ERROR! | E11: =CONCATENATE(left(E4,3), right(E5,2)) -> -1-1 | F11: =F9+G9 -> 0 | I11: =MID(H8,2,1) | K11: =MID(H8,1,1)-1 -> -1 | L11: =G8-1 -> -1 | N11: =N8+2 -> 3 | O11: =O8+2 -> 5 | P11: =N9 -> 1.5 | Y11: =AA9+AB9 -> 51 | Z11: =Y11*30 -> 1530
C12: =A1*B1 -> 0 | D12: =B1+C3 -> 1 | F12: =G9+H9 -> 0 | I12: =MID(H8,1,1)*2 -> 0 | J12: =I12-1 -> -1 | K12: =mid(H8,2,1)/3 -> 0 | L12: =MID(H8,2,1)-H7 -> -1 | N12: =N11-1 -> 2 | O12: =O11-1 -> 4 | P12: =P11-1 -> 0.5 | Y12: =AA10+AB10 -> 156 | Z12: =Y12*13 -> 2028
B13: 0 become 9 | C13: =C3 -> 1 | D13: =B1-1 -> -1 | E13: =A1 | I13: =mid(C6,2,1) | J13: =I13-1 -> -1 | K13: =mid(C7,1,1)-C8 -> -1 | L13: =mid(C7,1,1) | N13: =N12-1 -> 1 | O13: =O12-1 -> 3 | P13: =P12+1 -> 1.5
A14: reference | B14: result | C14: =D9-1 -> 1 | D14: =D9+C9 -> 4 | E14: =E9 -> 1 | I14: =mid(C6,1,1) -> 0 | J14: =I14-1 -> -1 | K14: =mid(D7,1,1) | L14: =mid(D7,2,1) | N14: =I8-2 -> -1 | O14: =K8 -> 2 | P14: =L8*2 -> -4 | Y14: =5150 -> 5150
B15: 107 | C15: =D13 -> -1 | D15: =D13+E13 -> -1 | E15: =E14-1 -> 0 | I15: =mid(D4,1,1)+mid(D4, 2,1) -> 1 | K15: =mid(C4,2,1) | L15: =mid(C6,1,1) -> 0 | N15: =MID(H8,1,1)+1 -> 1 | O15: =MID(H8,2,1)+1 -> 1 | P15: =O15+H7 -> 2 | Y15: =Y14-SUM(Z11:Z12) -> 1592
A16: Matches exactly, sometime middle in the other places | B16: =CONCATENATE(A7,A9,B4) -> 00 | F16: =MID(C6,1,1) -> 0 | G16: =MID(C4,2,1)-mid(D4,1,1) -> -1 | H16: =MID(D4,2,1) | I16: =mid(G8,2,1) | K16: =MID(G8,1,1)-1 -> -1 | L16: =mid(C4,1,1) | N16: =MID(L11,1,1) -> - | O16: =MID(L11,2,1)+3 -> 4 | P16: =L12*3 -> -3
A17: 62 | B17: =data!B17 -> 3 | C17: =E13 | D17: =D13 -> -1 | E17: =D14+1 -> 5 | F17: =MID(I17,1,1) | G17: =MID(I17,2,1) | H17: =MID(I17,3,1) | I17: =MID(G8,2,1) | K17: =MID(G8,1,1)-1 -> -1 | L17: =G7 | N17: =O12 -> 4 | O17: =if(O11=8,5,O11) -> 5 | P17: =O13 -> 3
A18: 26 | C18: =C17 | D18: =C17-D17 -> 1 | E18: =E17 -> 5 | F18: =MID(C4,1,1)+1 -> 1 | G18: =mid(C4,2,1) + mid(D4,1,1) -> 1 | H18: =mid(D4,2,1)-1 -> -1 | I18: =mid(D6,3,1) | L18: =mid(D7,2,1)
A19: =ABs(A17-B17) -> 59 | C19: =D6 -> 1 | D19: =LEFT(C6,2) -> 0 | I19: =I17/2 -> 0 | K19: =K11 -> -1 | L19: =L17+1 -> 1
A20: =abs(A18-B17) -> 23 | C20: =concatenate(right(D18, 1), left(D18,1)) -> 11 | I20: =I10 -> 2 | K20: =I11 | L20: =I12-1 -> -1 | S20: =O20+P20 -> 0 | T20: =Q20 | U20: =P20
A21: =A19+A20 -> 82 | F21: =G18 -> 1 | G21: =F18 -> 1 | H21: =H18 -> -1 | I21: =MID(H8,1,1)+MID(H8,2,1) -> 0 | L21: =H7 -> 1
A22: =A20*A19 -> 1357 | E22: check this for last digit - winwin / FF first digit | F22: =I6 | G22: =K6+1 -> 1 | H22: =L6-1 -> -1
F23: =I5-1 -> -1 | G23: =K5-1 -> -2 | H23: =L5
E24: check this option for middle digit | G24: =K1-1 -> 0 | H24: =H23/F26 -> 0
A25: 1. prevous result last 2 digit, support digit | F25: =I6+1 -> 1 | G25: =F25+K6 -> 1 | H25: =K6+L6 -> 0 | I25: Pefect match - just replace 20 as 00 is | K25: =CONCATENATE(mid(I35,1,1),mid(I35,2,1),mid(I35,3,1)-2) -> -2-2
A26: 1. prevous result last 2 digit, A17, A18 | F26: =F23-D37 -> -1 | G26: =K10 -> -1 | H26: =0 -> 0 | K26: =CONCATENATE(mid(I35,1,1),mid(I35,2,1),mid(I35,3,1)/2) -> -20
F27: =H25-1 -> -1 | G27: =G25 -> 1 | H27: =H25+G25 -> 1 | I27: 214 become 294 | P27: 503
A28: 49 | D28: =sqft(629) -> #NAME? | E28: somthing to check | F28: =0 -> 0 | G28: =G27 -> 1 | H28: =F27-1 -> -2 | I28: BT check | K28: =CONCATENATE(A1+1,B1+1,C3+1) -> 112 | L28: =Concatenate(MID(K28,4,1)-MID(K28,3,1),MID(K28,2,1),MID(K28,1,1)) -> -211 | P28: 793 | T28: 69 | U28: 96 | V28: 960
A29: 62 | E29: check this color for first digit or last digit | F29: =F22 | H29: =G22 -> 1 | K29: sometime reverse, -1 added as 1 with all numbers - KN PLUS - first two digit match Sometime, Middle digit matches | O29: 541 | P29: 229 | T29: 963 | U29: 369 | V29: 769
A30: =A28*A29 -> 3038 | F30: =C30-B1 -> 0 | G30: =F30+1 -> 1 | H30: =D30
A31: =A28*left(A29, 1) -> 294 | E31: check this color for first digit or last digit | F31: =#REF! -> #REF! | G31: =G26-1 -> -2 | H31: =H26+2 -> 2 | I31: become 002 - also matches first and last digit | K31: =CONCATENATE(mid(I35,1,1),mid(I35,2,1),mid(I35,3,1)+2) -> -22 | P31: 519 | T31: 967 | U31: 69
A32: =A28*right(A29, 1) -> 98 | E32: check this color for first digit or last digit | F32: =C27+2 -> 2 | G32: =D27+2 -> 2 | H32: =E27+1 -> 1 | K32: =CONCATENATE(mid(I35,3,1)+2,mid(I35,2,1),mid(I35,1,1)) -> 22-
A33: =A28*(A29+1) -> 3087 | E33: =CONCATENATE(B33+MID(C33,1,1),MID(C33,2,1)) -> 0 | F33: =N10-1 -> 3 | G33: =F33+1 -> 4 | H33: =P10 -> 6 | M33: =T10
A34: =A28*(A29+2) -> 3136 | E34: - 1 or +1 or 1, 2 or 2, 1 or 2, 3 or 3,2 on these digits, 1, 3 | F34: =F23-1 -> -2 | G34: =G23 -> -2 | H34: =H23 | I34: =CONCATENATE(F34,G34,H34) -> -2-2 | K34: Sometime matches AS IS - firstime
A35: =A28*(A29-1) -> 2989 | E35: SK - 226 - multiply by 3, 2, divide by 2,3 | F35: =G23 -> -2 | G35: =F28 -> 0 | H35: =G24 -> 0 | I35: =CONCATENATE(F35,G35,H35) -> -200 | K35: Check this - drop 1 from first /last
A36: =A28*(A29-2) -> 2940 | I36: =CONCATENATE(F36,G36,H36) | K36: 343, 041 = 400 (433-033) | O36: 813
E37: +,-,- | F37: =2 -> 2 | G37: =F25+1 -> 2 | H37: =G25+1 -> 2 | K37: BACKWARD - THINK ABOUT - VALUE | L37: =54-12 -> 42 | O37: 904
F38: =E26 | G38: =E25 | H38: =E24 -> check this option for middle digit | I38: =CONCATENATE(F38,G38,H38) -> check this option for middle digit | K38: backward - THINK ABOUT - VALUE
F39: =H38 -> check this option for middle digit | G39: =G38 | H39: =F38 | I39: =CONCATENATE(F39,G39,H39) -> check this option for middle digit
F40: =F39 -> check this option for middle digit | G40: =F40-G39 -> #VALUE! | H40: =H39-H39 -> 0
...

Sheet Copy of data
A1: =B16 -> 38 | B1: =A18 -> 26 | D1: 4 | E1: Total | F1: =MID(SUM(A$1:C$1),1,1) -> 6 | G1: =IF(LEN(SUM(A$1:C$1))>1,MID(SUM(A$1:C$1),2,1),0) -> 4 | H1: =SUM(F1+G1) -> 10 | I1: =MID(D4,1,1) -> 9 | K1: =mid(D4,2,1) -> 8 | M1: =mid(C4,2,1)-1 -> -1 | O1: =mid(D3,2,1) -> 8 | P1: =mid(D3,1,1)*mid(C3,2,1) -> 0 | Q1: =mid(C3,1,1) -> 0 | T1: 328 | V1: F | X1: S | AD1: L
C2: =A1+B1 -> 64 | D2: =C1*2 -> 0 | E2: =C2*C2 -> 4096
A3: =MID(D5,1,1) -> - | B3: =mid(D5,2,1) -> 2 | C3: =A1*C1 -> 0 | D3: =A1*B1 -> 988 | E3: =D4*D4 -> 976144 | F3: =H1 -> 10 | G3: =G1 -> 4 | H3: =F1 -> 6 | I3: =mid(D5,1,1) -> - | K3: =mid(D5,2,1) -> 2 | M3: =mid(D6,1,1) + mid(D6,2,1) -> 8 | O3: =F6 -> -1 | P3: =H6-G6 -> -26 | Q3: =G6 -> 26 | U3: F | V3: =I6 | X3: =CONCAT($V3,X$2) | Y3: =CONCAT($V3,Y$2) | Z3: =CONCAT($V3,Z$2) | AA3: =CONCAT($V3,AA$2) | AB3: =CONCAT($V3,AB$2) | AC3: =CONCAT($V3,AC$2)
A4: =mid(D5,3,1) -> 6 | B4: 0 | C4: =B1*C1 -> 0 | D4: =B1*A1 -> 988 | E4: =C4*D4 -> 0 | F4: =F1 -> 6 | G4: =H1 -> 10 | H4: =G1 -> 4 | I4: =mid(C5,2,1) -> 8 | K4: =mid(C5,1,1)-1 -> 2 | M4: =mid(C6,1,1) -> 8
C5: =A1+C1 -> 38 | D5: =C1-B1 -> -26 | E5: =D5*C5 -> -988 | F5: =A1 -> 38 | G5: =C1 | H5: =B1-3 -> 23 | I5: =mid(C6,2,1) | K5: =mid(C6,2,1)-mid(C5,2,1) -> -8 | M5: =mid(C5,1,1)+mid(C5, 2,1) -> 11
A6: =MID(C5,1,1) -> 3 | B6: =MID(C5,2,1) -> 8 | C6: =mid(D3,3,1) -> 8 | D6: =MID(D3,2,1) -> 8 | E6: KARUNYA PLUS - sometime matches the result, otherwise take values from here and down think about add 3 and divide 3 last two digits | F6: =CONCATENATE(MID(C3,1,1))-1 -> -1 | G6: =B1 -> 26 | H6: =C1 | I6: =MID(H7,2,1) | J6: =I6 | K6: =MID(H7,1,1)+2 -> 2 | M6: =H6-2 -> -2 | O6: =M7 -> -2 | P6: =M7*K7 -> -4 | Q6: =I7-M7 -> 2 | V6: PICK
A7: =MID(C5,3,1) | B7: 0 | C7: =mid(D3,1,1) -> 9 | D7: 0 | E7: sometime +1, -1 on first and last digit, +2, -2 on two digits | F7: =CONCATENATE(MID(C4,1,1))+1 -> 1 | G7: =CONCATENATE(MID(C3,2,1))*MID(D3,1,1) -> 0 | H7: =CONCATENATE(MID(C3,2,1))*MID(C3,2,1) -> 0 | I7: =H6 | J7: =mid(H6,1,1)-1 -> -1 | K7: =mid(H7,1,1)+2 -> 2 | M7: =mid(H7,2,1)-2 -> -2 | O7: =IF(I7=5,8,I7) | P7: =K7+1 -> 3 | Q7: =M7-1 -> -3 | R7: if values is 0 consider as 9 | AB7: =123*13 -> 1599
C8: =2 -> 2 | D8: =C1+1 -> 1 | E8: =B1+1 -> 27 | F8: =B19 | G8: =B21 | H8: =B20 | I8: =Mid(H7,1,1)+1 -> 1 | J8: =mid(H7,1,1) -> 0 | K8: =MID(H7,2,1)+2 -> 2 | M8: =H6 | O8: =P7/2 -> 1.5 | P8: =O7-Q7 -> 3 | Q8: =P8-Q7 -> 6 | AB8: 25 | AC8: 26
C9: =A1*B1 -> 988 | D9: =B1*C1 -> 0 | E9: =CONCATENATE(left(E2,3), right(E3,2)) -> 40944 | F9: =F8+H8 -> 0 | G9: =CONCATENATE(MID(E47,2,1)) -> 7 | H9: =CONCATENATE(MID(E47,3,1)) -> 2 | I9: =MID(H7,1,1)+2 -> 2 | K9: =MID(H7, 2,1)-1 -> -1 | M9: =H6 | O9: =I9*2 -> 4 | P9: =O9-K9 -> 5 | Q9: =P9+M9 -> 5 | AB9: 123 | AC9: 33
B10: 8 become 5 | C10: =B1+C1 -> 26 | D10: =C10*A1 -> 988 | E10: =CONCATENATE(left(E3,3), right(E4,2)) -> 9760 | F10: =F8+G8 -> 0 | I10: =MID(H7,2,1) | K10: =MID(H7,1,1)-1 -> -1 | M10: =G7-1 -> -1 | O10: =O7+2 -> 2 | P10: =P7+2 -> 5 | Q10: =O8 -> 1.5 | Z10: =AB8+AC8 -> 51 | AA10: =Z10*30 -> 1530
C11: =A1*B1 -> 988 | D11: =B1+C1 -> 26 | F11: =G8+H8 -> 0 | I11: =MID(H7,1,1)*2 -> 0 | J11: =I11-1 -> -1 | K11: =mid(H7,2,1)/3 -> 0 | M11: =MID(H7,2,1)-H6 -> 0 | O11: =O10-1 -> 1 | P11: =P10-1 -> 4 | Q11: =Q10-1 -> 0.5 | Z11: =AB9+AC9 -> 156 | AA11: =Z11*13 -> 2028
B12: 0 become 9 | C12: =C1 | D12: =B1-1 -> 25 | E12: =A1 -> 38 | I12: =mid(C5,2,1) -> 8 | J12: =I12-1 -> 7 | K12: =mid(C6,1,1)-C7 -> -1 | M12: =mid(C6,1,1) -> 8 | O12: =O11-1 -> 0 | P12: =P11-1 -> 3 | Q12: =Q11+1 -> 1.5
A13: reference | B13: result | C13: =D8-1 -> 0 | D13: =D8+C8 -> 3 | E13: =E8 -> 27 | I13: =mid(C5,1,1) -> 3 | J13: =I13-1 -> 2 | K13: =mid(D6,1,1) -> 8 | M13: =mid(D6,2,1) | O13: =I7-2 -> -2 | P13: =K7 -> 2 | Q13: =M7*2 -> -4 | Z13: =5150 -> 5150
A14: 25.059928 | B14: 107 | C14: =D12 -> 25 | D14: =D12+E12 -> 63 | E14: =E13-1 -> 26 | I14: =mid(D3,1,1)+mid(D3, 2,1) -> 17 | K14: =mid(C3,2,1) | M14: =mid(C5,1,1) -> 3 | O14: =MID(H7,1,1)+1 -> 1 | P14: =MID(H7,2,1)+1 -> 1 | Q14: =P14+H6 -> 1 | Z14: =Z13-SUM(AA10:AA11) -> 1592
A15: Matches exactly, sometime middle in the other places | F15: =MID(C5,1,1) -> 3 | G15: =MID(C3,2,1)-mid(D3,1,1) -> -9 | H15: =MID(D3,2,1) -> 8 | I15: =mid(G7,2,1) | K15: =MID(G7,1,1)-1 -> -1 | M15: =mid(C3,1,1) -> 0 | O15: =MID(M10,1,1) -> - | P15: =MID(M10,2,1)+3 -> 4 | Q15: =M11*3 -> 0
A16: 12 | B16: 38 | C16: =E12 -> 38 | D16: =D12 -> 25 | E16: =D13+1 -> 4 | F16: =MID(I16,1,1) | G16: =MID(I16,2,1) | H16: =MID(I16,3,1) | I16: =MID(G7,2,1) | K16: =MID(G7,1,1)-1 -> -1 | M16: =G6 -> 26 | O16: =P11 -> 4 | P16: =if(P10=8,5,P10) -> 5 | Q16: =P12 -> 3
A17: 35 | C17: =C16 -> 38 | D17: =C16-D16 -> 13 | E17: =E16 -> 4 | F17: =MID(C3,1,1)+1 -> 1 | G17: =mid(C3,2,1) + mid(D3,1,1) -> 9 | H17: =mid(D3,2,1)-1 -> 7 | I17: =mid(D5,3,1) -> 6 | M17: =mid(D6,2,1)
A18: =ABs(A16-B16) -> 26 | I18: =I16/2 -> 0 | K18: =K10 -> -1 | M18: =M16+1 -> 27
A19: =abs(A17-B16) -> 3 | I19: =I9 -> 2 | K19: =I10 | M19: =I11-1 -> -1 | O19: SD | P19: =CONCATENATE(P14,O14,O15) -> 11- | R19: =P19*P20 -> #VALUE! | T19: =P19+Q19 -> #VALUE! | U19: =R19 -> #VALUE! | V19: =Q19
A20: =A18+A19 -> 29 | F20: =G17 -> 9 | G20: =F17 -> 1 | H20: =H17 -> 7 | I20: =MID(H7,1,1)+MID(H7,2,1) -> 0 | M20: =H6 | O20: FD | P20: =CONCATENATE(data!N17,data!N16,data!O16) -> 4-4 | Q20: =CONCATENATE(O14,O15+1,O16) -> #VALUE! | R20: =SQRTPI(R19) -> #VALUE!
A21: =A19*A18 -> 78 | E21: check this for last digit - winwin / FF first digit | F21: =I5 | G21: =K5+1 -> -7 | H21: =M5-1 -> 10 | O21: FD | P21: =concatenate(I12-1, I13, I14) -> 7317
F22: =I4-1 -> 7 | G22: =K4-1 -> 1 | H22: =M4 -> 8 | O22: FD | P22: =M18 -> 27
E23: check this option for middle digit | G23: =K1-1 -> 7 | H23: =H22/F25 -> 1.1428571 | P23: =CONCATENATE(Q16-P16,P16,O17) -> -25 | R23: =Q22-Q23 -> 0
F24: =I5+1 -> 1 | G24: =F24+K5 -> -7 | H24: =K5+M5 -> 3 | I24: Pefect match - just replace 20 as 00 is | K24: =CONCATENATE(mid(I34,1,1),mid(I34,2,1),mid(I34,3,1)-2) -> 105 | R24: =R23*Q24 -> 0
F25: =F22-D36 -> 7 | G25: =K9 -> -1 | H25: =0 -> 0 | K25: =CONCATENATE(mid(I34,1,1),mid(I34,2,1),mid(I34,3,1)/2) -> 103.5
F26: =H24-1 -> 2 | G26: =G24 -> -7 | H26: =H24+G24 -> -4 | I26: 214 become 294 | V26: 481 | Y26: =SQRTPI(V26) -> 38.872948
D27: =sqft(629) -> #NAME? | E27: somthing to check | F27: =0 -> 0 | G27: =G26 -> -7 | H27: =F26-1 -> 1 | I27: BT check | K27: =CONCATENATE(A1+1,B1+1,C1+1) -> 39271 | M27: =Concatenate(MID(K27,4,1)-MID(K27,3,1),MID(K27,2,1),MID(K27,1,1)) -> 593
E28: check this color for first digit or last digit | F28: =F21 | H28: =G21 -> -7 | K28: sometime reverse, -1 added as 1 with all numbers - KN PLUS - first two digit match Sometime, Middle digit matches
F29: =C29-B1 -> -26 | G29: =F29+1 -> -25 | H29: =D29
E30: check this color for first digit or last digit | F30: =#REF! -> #REF! | G30: =G25-1 -> -2 | H30: =H25+2 -> 2 | I30: become 002 - also matches first and last digit | K30: =CONCATENATE(mid(I34,1,1),mid(I34,2,1),mid(I34,3,1)+2) -> 109
E31: check this color for first digit or last digit | F31: =C26+2 -> 2 | G31: =D26+2 -> 2 | H31: =E26+1 -> 1 | K31: =CONCATENATE(mid(I34,3,1)+2,mid(I34,2,1),mid(I34,1,1)) -> 901
E32: =CONCATENATE(B32+MID(C32,1,1),MID(C32,2,1)) -> 0 | F32: =O9-1 -> 3 | G32: =F32+1 -> 4 | H32: =Q9 -> 5 | N32: =U9
A33: BC | B33: =D17 -> 13 | E33: - 1 or +1 or 1, 2 or 2, 1 or 2, 3 or 3,2 on these digits, 1, 3 | F33: =F22-1 -> 6 | G33: =G22 -> 1 | H33: =H22 -> 8 | I33: =CONCATENATE(F33,G33,H33) -> 618 | K33: Sometime matches AS IS - firstime
E34: SK - 226 - multiply by 3, 2, divide by 2,3 | F34: =G22 -> 1 | G34: =F27 -> 0 | H34: =G23 -> 7 | I34: =CONCATENATE(F34,G34,H34) -> 107 | K34: Check this - drop 1 from first /last
I35: =CONCATENATE(F35,G35,H35) | K35: 343, 041 = 400 (433-033) | P35: 813
E36: +,-,- | F36: =2 -> 2 | G36: =F24+1 -> 2 | H36: =G24+1 -> -6 | K36: BACKWARD - THINK ABOUT - VALUE | P36: 904
F37: =E25 | G37: =E24 | H37: =E23 -> check this option for middle digit | I37: =CONCATENATE(F37,G37,H37) -> check this option for middle digit | K37: backward - THINK ABOUT - VALUE
F38: =H37 -> check this option for middle digit | G38: =G37 | H38: =F37 | I38: =CONCATENATE(F38,G38,H38) -> check this option for middle digit
F39: =F38 -> check this option for middle digit | G39: =F39-G38 -> #VALUE! | H39: =H38-H38 -> 0
F40: =E29 | G40: =E31 -> check this color for first digit or last digit | H40: =E30 -> check this color for first digit or last digit | K40: =CONCATENATE(A1+1,B1-1,C1-1) -> 3925-1 | M40: =CONCATENATE(MID(K40,1,1),MID(K40,2,1),MID(K40,4,1)) -> 395
...

Sheet Copy of Copy of data
A1: =CONCAT(Victory!AC134,Victory!AD134) -> 83 | B1: =Victory!AE134 | D1: 4 | E1: Total | F1: =MID(SUM(A$1:C$1),1,1) -> 0 | G1: =IF(LEN(SUM(A$1:C$1))>1,MID(SUM(A$1:C$1),2,1),0) -> 0 | H1: =SUM(F1+G1) -> 0 | I1: =MID(D4,1,1) -> 0 | K1: =mid(D4,2,1) | M1: =mid(C4,2,1)-1 -> -1 | O1: =mid(D3,2,1) | P1: =mid(D3,1,1)*mid(C3,2,1) -> 0 | Q1: =mid(C3,1,1) -> 0 | T1: 328 | V1: F | X1: S | AD1: L
C2: =A1+B1 -> 83 | D2: =C1*2 -> 0 | E2: =C2*C2 -> 6889
A3: =MID(D5,1,1) -> 0 | B3: =mid(D5,2,1) | C3: =A1*C1 -> 0 | D3: =A1*B1 -> 0 | E3: =D4*D4 -> 0 | F3: =H1 -> 0 | G3: =G1 -> 0 | H3: =F1 -> 0 | I3: =mid(D5,1,1) -> 0 | K3: =mid(D5,2,1) | M3: =mid(D6,1,1) + mid(D6,2,1) -> 0 | O3: =F6 -> -1 | P3: =H6-G6 -> 0 | Q3: =G6 | U3: F | V3: =I6 | X3: =CONCAT($V3,X$2) | Y3: =CONCAT($V3,Y$2) | Z3: =CONCAT($V3,Z$2) | AA3: =CONCAT($V3,AA$2) | AB3: =CONCAT($V3,AB$2) | AC3: =CONCAT($V3,AC$2)
A4: =mid(D5,3,1) | B4: 0 | C4: =B1*C1 -> 0 | D4: =B1*A1 -> 0 | E4: =C4*D4 -> 0 | F4: =F1 -> 0 | G4: =H1 -> 0 | H4: =G1 -> 0 | I4: =mid(C5,2,1) -> 3 | K4: =mid(C5,1,1)-1 -> 7 | M4: =mid(C6,1,1)
C5: =A1+C1 -> 83 | D5: =C1-B1 -> 0 | E5: =D5*C5 -> 0 | F5: =A1 -> 83 | G5: =C1 | H5: =B1-3 -> -3 | I5: =mid(C6,2,1) | K5: =mid(C6,2,1)-mid(C5,2,1) -> -3 | M5: =mid(C5,1,1)+mid(C5, 2,1) -> 11
A6: =MID(C5,1,1) -> 8 | B6: =MID(C5,2,1) -> 3 | C6: =mid(D3,3,1) | D6: =MID(D3,2,1) | E6: KARUNYA PLUS - sometime matches the result, otherwise take values from here and down think about add 3 and divide 3 last two digits | F6: =CONCATENATE(MID(C3,1,1))-1 -> -1 | G6: =B1 | H6: =C1 | I6: =MID(H7,2,1) | J6: =I6 | K6: =MID(H7,1,1)+2 -> 2 | M6: =H6-2 -> -2 | O6: =M7 -> -2 | P6: =M7*K7 -> -4 | Q6: =I7-M7 -> 2 | V6: PICK
A7: =MID(C5,3,1) | B7: 0 | C7: =mid(D3,1,1) -> 0 | D7: 0 | E7: sometime +1, -1 on first and last digit, +2, -2 on two digits | F7: =CONCATENATE(MID(C4,1,1))+1 -> 1 | G7: =CONCATENATE(MID(C3,2,1))*MID(D3,1,1) -> 0 | H7: =CONCATENATE(MID(C3,2,1))*MID(C3,2,1) -> 0 | I7: =H6 | J7: =mid(H6,1,1)-1 -> -1 | K7: =mid(H7,1,1)+2 -> 2 | M7: =mid(H7,2,1)-2 -> -2 | O7: =IF(I7=5,8,I7) | P7: =K7+1 -> 3 | Q7: =M7-1 -> -3 | R7: if values is 0 consider as 9 | AB7: =123*13 -> 1599
A8: ADD HERE LAST 3 DIGITS FORWARD OR REVERSE | C8: =2 -> 2 | D8: =C1+1 -> 1 | E8: =B1+1 -> 1 | F8: =B19 -> 1 | G8: =B21 -> -3 | H8: =B20 -> 1 | I8: =Mid(H7,1,1)+1 -> 1 | J8: =mid(H7,1,1) -> 0 | K8: =MID(H7,2,1)+2 -> 2 | M8: =H6 | O8: =P7/2 -> 1.5 | P8: =O7-Q7 -> 3 | Q8: =P8-Q7 -> 6 | AB8: 25 | AC8: 26
A9: AB/AC | B9: Result | C9: =A1*B1 -> 0 | D9: =B1*C1 -> 0 | E9: =CONCATENATE(left(E2,3), right(E3,2)) -> 6880 | F9: =F8+H8 -> 2 | G9: =CONCATENATE(MID(E47,2,1)) | H9: =CONCATENATE(MID(E47,3,1)) | I9: =MID(H7,1,1)+2 -> 2 | K9: =MID(H7, 2,1)-1 -> -1 | M9: =H6 | O9: =I9*2 -> 4 | P9: =O9-K9 -> 5 | Q9: =P9+M9 -> 5 | AB9: 123 | AC9: 33
A10: =CONCAT(LEFT(E9,1),RIGHT(E9,1)) -> 60 | B10: =RIGHT(E9,3) -> 880 | C10: =B1+C1 -> 0 | D10: =C10*A1 -> 0 | E10: =CONCATENATE(left(E3,3), right(E4,2)) -> 00 | F10: =F8+G8 -> -2 | I10: =MID(H7,2,1) | K10: =MID(H7,1,1)-1 -> -1 | M10: =G7-1 -> -1 | O10: =O7+2 -> 2 | P10: =P7+2 -> 5 | Q10: =O8 -> 1.5 | Z10: =AB8+AC8 -> 51 | AA10: =Z10*30 -> 1530
A11: =concat(MID(C4,2,1),RIGHT(C4,1)) -> 0 | B11: =C5 -> 83 | C11: =A1*B1 -> 0 | D11: =B1+C1 -> 0 | F11: =G8+H8 -> -2 | I11: =MID(H7,1,1)*2 -> 0 | J11: =I11-1 -> -1 | K11: =mid(H7,2,1)/3 -> 0 | M11: =MID(H7,2,1)-H6 -> 0 | O11: =O10-1 -> 1 | P11: =P10-1 -> 4 | Q11: =Q10-1 -> 0.5 | Z11: =AB9+AC9 -> 156 | AA11: =Z11*13 -> 2028
C12: =C1 | D12: =B1-1 -> -1 | E12: =A1 -> 83 | I12: =mid(C5,2,1) -> 3 | J12: =I12-1 -> 2 | K12: =mid(C6,1,1)-C7 -> 0 | M12: =mid(C6,1,1) | O12: =O11-1 -> 0 | P12: =P11-1 -> 3 | Q12: =Q11+1 -> 1.5
A13: BC/AB/AC | C13: =D8-1 -> 0 | D13: =D8+C8 -> 3 | E13: =E8 -> 1 | I13: =mid(C5,1,1) -> 8 | J13: =I13-1 -> 7 | K13: =mid(D6,1,1) | M13: =mid(D6,2,1) | O13: =I7-2 -> -2 | P13: =K7 -> 2 | Q13: =M7*2 -> -4 | Z13: =5150 -> 5150
A14: =RIGHT(E10,2) -> 00 | C14: =D12 -> -1 | D14: =D12+E12 -> 82 | E14: =E13-1 -> 0 | I14: =mid(D3,1,1)+mid(D3, 2,1) -> 0 | K14: =mid(C3,2,1) | M14: =mid(C5,1,1) -> 8 | O14: =MID(H7,1,1)+1 -> 1 | P14: =MID(H7,2,1)+1 -> 1 | Q14: =P14+H6 -> 1 | Z14: =Z13-SUM(AA10:AA11) -> 1592
A15: =right(B10,2) -> 80 | F15: =MID(C5,1,1) -> 8 | G15: =MID(C3,2,1)-mid(D3,1,1) -> 0 | H15: =MID(D3,2,1) | I15: =mid(G7,2,1) | K15: =MID(G7,1,1)-1 -> -1 | M15: =mid(C3,1,1) -> 0 | O15: =MID(M10,1,1) -> - | P15: =MID(M10,2,1)+3 -> 4 | Q15: =M11*3 -> 0
A16: =A14+1 -> 1 | C16: =E12 -> 83 | D16: =D12 -> -1 | E16: =D13+1 -> 4 | F16: =MID(I16,1,1) | G16: =MID(I16,2,1) | H16: =MID(I16,3,1) | I16: =MID(G7,2,1) | K16: =MID(G7,1,1)-1 -> -1 | M16: =G6 | O16: =P11 -> 4 | P16: =if(P10=8,5,P10) -> 5 | Q16: =P12 -> 3
C17: =C16 -> 83 | D17: =C16-D16 -> 84 | E17: =E16 -> 4 | F17: =MID(C3,1,1)+1 -> 1 | G17: =mid(C3,2,1) + mid(D3,1,1) -> 0 | H17: =mid(D3,2,1)-1 -> -1 | I17: =mid(D5,3,1) | M17: =mid(D6,2,1)
A18: PATH | B18: =H5 -> -3 | C18: =G6 | D18: =F7 -> 1 | I18: =I16/2 -> 0 | K18: =K10 -> -1 | M18: =M16+1 -> 1
B19: =F7 -> 1 | C19: =G6 | D19: =H5 -> -3 | I19: =I9 -> 2 | K19: =I10 | M19: =I11-1 -> -1 | O19: SD | P19: =CONCATENATE(P14,O14,O15) -> 11- | S19: AC
B20: =F7 -> 1 | C20: =H5 -> -3 | D20: =G6 | F20: =G17 -> 0 | G20: =F17 -> 1 | H20: =H17 -> -1 | I20: =MID(H7,1,1)+MID(H7,2,1) -> 0 | M20: =H6 | O20: FD | P20: =CONCATENATE(data!N17,data!N16,data!O16) -> 4-4 | Q20: =CONCATENATE(O14,O15+1,O16) -> #VALUE! | S20: =RIGHT(P20,2) -> -4
B21: =H5 -> -3 | C21: =F7 -> 1 | D21: =G6 | F21: =I5 | G21: =K5+1 -> -2 | H21: =M5-1 -> 10 | O21: FD | P21: =concatenate(I12-1, I13, I14) -> 280
C22: =B21-C21 -> -4 | D22: =D21 | E22: =CONCATENATE(G17,F20,G25) -> 00-1 | F22: =I4-1 -> 2 | G22: =K4-1 -> 6 | H22: =M4 | O22: FD | P22: =M18 -> 1
A23: A | C23: =B6 -> 3 | D23: =A6 -> 8 | G23: =K1-1 -> -1 | H23: =H22/F25 -> 0 | P23: =CONCATENATE(Q16-P16,P16,O17) -> -25
A24: =8*8 -> 64 | C24: =F26 -> 7 | D24: =H26 -> 6 | E24: =CONCAT(H31,H30) -> 12 | F24: =I5+1 -> 1 | G24: =F24+K5 -> -2 | H24: =K5+M5 -> 8 | I24: Pefect match - just replace 20 as 00 is | K24: =CONCATENATE(mid(I34,1,1),mid(I34,2,1),mid(I34,3,1)-2) -> #VALUE!
C25: =A6 -> 8 | D25: =B6 -> 3 | F25: =F22-D36 -> 2 | G25: =K9 -> -1 | H25: =0 -> 0 | K25: =CONCATENATE(mid(I34,1,1),mid(I34,2,1),mid(I34,3,1)/2) -> #VALUE!
D26: =A28 -> 10 | F26: =H24-1 -> 7 | G26: =G24 -> -2 | H26: =H24+G24 -> 6 | I26: 214 become 294 | Y26: =SQRTPI(V26) -> 0
A27: =H20 -> -1 | E27: CONTINUATION (BC OR AC) | F27: =0 -> 0 | G27: =G26 -> -2 | H27: =F26-1 -> 6 | I27: BT check | K27: =CONCATENATE(A1+1,B1+1,C1+1) -> 8411 | M27: =Concatenate(MID(K27,4,1)-MID(K27,3,1),MID(K27,2,1),MID(K27,1,1)) -> 048
A28: =H21 -> 10 | B28: =RIGHT(E2,1) -> 9 | D28: =SUM(left(E28,1)+RIGHT(E28)) -> 0 | E28: =LEFT(E3,2) -> 0 | F28: =F21 | H28: =G21 -> -2 | K28: sometime reverse, -1 added as 1 with all numbers - KN PLUS - first two digit match Sometime, Middle digit matches
A29: =H24 -> 8 | B29: =F26 -> 7 | E29: =Concatenate(LEFT(E2),RIGHT(E2)) -> 69 | F29: =#REF!-B1 -> #REF! | G29: =F29+1 -> #REF! | H29: =D29
A30: =H27 -> 6 | E30: =right(E9,2) -> 80 | F30: =#REF! -> #REF! | G30: =G25-1 -> -2 | H30: =H25+2 -> 2 | I30: become 002 - also matches first and last digit | K30: =CONCATENATE(mid(I34,1,1),mid(I34,2,1),mid(I34,3,1)+2) -> #VALUE!
A31: =LEFT(A14,1) -> 0 | F31: =C28+2 -> 2 | G31: =D26+2 -> 12 | H31: =E26+1 -> 1 | K31: =CONCATENATE(mid(I34,3,1)+2,mid(I34,2,1),mid(I34,1,1)) -> #VALUE!
A32: =H1 -> 0 | F32: =O9-1 -> 3 | G32: =F32+1 -> 4 | H32: =Q9 -> 5 | N32: =U9
F33: =F22-1 -> 1 | G33: =G22 -> 6 | H33: =H22 | I33: =CONCATENATE(F33,G33,H33) -> 16 | K33: Sometime matches AS IS - firstime
A34: AB - MATCH | B34: =LEFT(A10,1) -> 6 | F34: =G22 -> 6 | G34: =F27 -> 0 | H34: =G23 -> -1 | I34: =CONCATENATE(F34,G34,H34) -> 60-1 | K34: Check this - drop 1 from first /last
B35: =A30 -> 6 | I35: =CONCATENATE(F35,G35,H35) | K35: 343, 041 = 400 (433-033) | P35: 813
F36: =2 -> 2 | G36: =F24+1 -> 2 | H36: =G24+1 -> -1 | K36: BACKWARD - THINK ABOUT - VALUE | P36: 904
F37: =E25 | G37: =E24 -> 12 | H37: =E23 | I37: =CONCATENATE(F37,G37,H37) -> 12 | K37: backward - THINK ABOUT - VALUE
A38: ='Copy of Copy of data'!A6 -> 8 | B38: ='Copy of Copy of data'!B6 -> 3 | C38: ='Copy of Copy of data'!B3 | F38: =H37 | G38: =G37 -> 12 | H38: =F37 | I38: =CONCATENATE(F38,G38,H38) -> 12
A39: =E13 -> 1 | B39: =H5 -> -3 | C39: =C13 -> 0 | D39: Reverse (995 for 048) | F39: =F38 | G39: =F39-G38 -> -12 | H39: =H38-H38 -> 0
A40: =F11 -> -2 | B40: =F10 -> -2 | C40: =A39 -> 1 | D40: Result | F40: =E29 -> 69 | G40: =E31 | H40: =E30 -> 80 | K40: =CONCATENATE(A1+1,B1-1,C1-1) -> 84-1-1 | M40: =CONCATENATE(MID(K40,1,1),MID(K40,2,1),MID(K40,4,1)) -> 841
...

Sheet Victory
AB1: *,,,,,+
A2: =A40 -> 426 | B2: =MID(A2,3,1) -> 6 | C2: =IF(B2=9,0,B2+1) -> 7 | D2: =MOD(B2+2,10) -> 8 | E2: =B2 -> 6 | F2: =IF(B2<=4,MOD(B2+1,10),MOD(B2-1,10)) -> 5 | J2: =G2 | K2: =G2+F1 -> 0 | L2: =G1-G2 -> 0 | N2: =F1 | O2: =F2 -> 5 | Q2: =G1+1 -> 1 | S2: =G1-1 -> -1 | T2: =G2-1 -> -1 | U2: =F2+1 -> 6
N3: =G1 | O3: =F2 -> 5 | Q3: =F1-1 -> -1 | S3: =G1+1 -> 1 | T3: =G2+1 -> 1 | U3: =F2-1 -> 4
J4: =F4+1 -> 1 | K4: =F5 | L4: =F5-G4 -> 0 | N4: =F4 | O4: =F5 | Q4: =G4-1 -> -1
J5: =G4 | K5: =F5 | L5: =F4-1 -> -1 | N5: =G4-1 -> -1 | O5: =F4 | Q5: =G5
A6: 651 | J6: =G4-1 -> -1 | K6: =F4 | L6: =F4*F5 -> 0 | N6: =G1-G2 -> 0 | O6: =F1-1 -> -1 | Q6: =O6*G2 -> 0
H7: no change for this
E10: =data!G8 -> 0 | G10: =data!H8 -> 0 | O10: sum the digits
E11: =data!G7 | G11: =data!H7 -> 1
O12: =I13 -> 0 | Q12: =I16 -> 0 | R12: =K21 -> -1
F13: =ABS(data!G43) -> 2 | G13: =SUM(#REF!,F13) -> #REF! | H13: AB | I13: =CONCAT(MID(G10,2,1),MID(G10,1,1)) -> 0 | J13: =CONCAT(MID(G10,1,1),MID(G10,2,1)) -> 0 | K13: =CONCAT(MID(G11,1,1),MID(data!H8,1,1)) -> 10 | L13: =CONCAT(MID(G11,1,1)-1,MID(data!H8,1,1)) -> 00 | M13: =CONCAT(MID(data!G8,1,1),MID(data!H7,1,1)) -> 01 | N13: =CONCAT(MID(data!H8,1,1)-3,MID(data!H8,2,1)+1) -> -31 | O13: =M16 -> 11 | Q13: =K13 -> 10 | R13: =J19 -> 0 | V13: 648 | Z13: 907 | AB13: 970 | AD13: 864 | AF13: =AB13-AD13 -> 106
E14: A | F14: B | G14: C | I14: =CONCAT(MID(data!H8,1,1)+1,MID(data!H8,2,1)-1) -> 1-1 | J14: =CONCAT(MID(data!H7,1,1),MID(data!G8,1,1)+MID(data!G8,2,1)) -> 10 | K14: =CONCAT(data!I13,data!I14+1) -> 1 | L14: =CONCAT(MID(data!G8,2,1)-MID(data!H7,1,1),MID(data!G7,1,1)-1) -> -1-1 | M14: =CONCAT(MID(K14,2,1),MID(K14,1,1)) -> 1 | N14: =CONCAT(MID(I13,1,1)+1,MID(I13,1,1)-MID(I13,2,1)) -> 10 | O14: =J16 -> 3- | Q14: =J21 -> 3 | AF14: =Z13-V13 -> 259
E15: =data!K9 -> 2 | F15: =data!H1 -> 0 | G15: =data!I4 -> 1 | I15: =CONCAT(E10-MID(G10,1,1),MID(G10,1,1)) -> 00 | J15: reverse 61 - 14 | O15: =J16 -> 3- | Q15: =N21 -> 33 | R15: =I13 -> 0 | V15: 507 | Z15: 746 | AB15: 764 | AD15: 750 | AF15: =AB15-AD15 -> 14
E16: =data!K11 -> -1 | F16: =data!K4 | G16: =F27 -> 2 | H16: BC | I16: =CONCAT(MID(data!G8,1,1),MID(data!G8,2,1)) -> 0 | J16: =CONCAT(MID(N13,2,1),MID(L19,2,1)) -> 3- | K16: =CONCAT(MID(K13,1,1),MID(K13,2,1)+1) -> 11 | L16: =CONCAT(MID(L14,2,1),MID(data!G8,1,1)) -> 10 | M16: =CONCAT(data!I8,data!L9) -> 11 | N16: =CONCAT(MID(N14,2,1),data!F7) -> 0-1 | O16: =J16 -> 3- | Q16: =L16 -> 10 | AF16: =Z15-V15 -> 239
C17: Result | E17: =G22 -> 0 | F17: =F23 | G17: =E23 -> 2 | I17: =MID(I24,2,1) -> 0 | L17: B | M17: {=UNIQUE(TRANSPOSE(F15:F33))} -> 0 | P17: -1 | Q17: 2 | R17: 2 | S17: -1 | T17: -1 | V17: 4 | X17: 0 | Y17: 2 | Z17: 0 | AB17: 0 | AC17: 0 | AE17: 2
E18: =data!I11 | F18: =data!L12 -> -1 | G18: =data!L7 -> -1 | I18: =G10 -> 0 | O18: =I13 -> 0 | Q18: =J13 -> 0 | R18: =I16 -> 0
E19: =data!I10 -> 2 | F19: =data!K7 -> 2 | G19: =data!L7 -> -1 | H19: AC | I19: =CONCAT(data!H4,data!H1) -> 00 | J19: =CONCAT(MID(data!G8,1,1),MID(data!G7,1,1)) -> 0 | K19: =CONCAT(MID(data!G8,1,1),MID(data!G7,1,1)-1) -> 0-1 | L19: =CONCAT(MID(N13,1,1),MID(data!G7,1,1)-3) -> --3 | M19: =CONCAT(MID(I14,1,1),MID(data!G7,1,1)) -> 1 | N19: =CONCAT(MID(K13,1,1),mid(data!G8,1,1)) -> 10 | AF19: =987-430 -> 557
E20: =data!K15 | F20: =data!N12 -> 2 | G20: =data!P15 -> 2 | O20: =K21 -> -1 | Q20: =J16 -> 3- | R20: =K21 -> -1 | V20: 430 | Z20: 879 | AE20: =987-943 -> 44 | AF20: =Z20-V20 -> 449
A21: Do Reverse and apply logic | C21: Result | E21: =data!L19 -> 1 | F21: =data!K19 -> -1 | G21: =data!I19 -> 0 | I21: =CONCAT(data!I14+1,data!I10) -> 12 | J21: =CONCAT(data!I10+data!I9,data!I13) -> 3 | K21: =CONCAT(MID(L14,1,1),MID(M16,2,1)) -> -1 | L21: =CONCAT(data!H7,data!F7) -> 1-1 | M21: =CONCAT(MID(N14,1,1),MID(N16,2,1)) -> 1- | N21: =CONCAT(MID(O14,1,1),MID(O16,1,1)) -> 33 | R21: =8*7 -> 56
C22: Result | E22: =data!I19 -> 0 | F22: =data!K19 -> -1 | G22: =data!L6 -> 0
C23: Result | E23: =F13 -> 2 | F23: =F37 | G23: =F16
C24: Result | E24: =data!I9 -> 1 | F24: =data!O9 -> 4 | G24: =data!I19 -> 0 | I24: =CONCAT(I19,M19) -> 001 | K24: RS- 30
C26: Result | E26: =#REF! -> #REF! | F26: =F28 -> 0 | G26: =G28 -> 0 | H26: =MID(I24,3,1) -> 1 | I26: =MID(I24,1,1) -> 0 | J26: =mid(I21, 2,1)+mid(J21, 2,1) -> 2 | K26: =mid(I21, 1,1) -> 1 | L26: =mid(J21, 1,1) -> 3 | M26: {=UNIQUE(TRANSPOSE(E15:E33))} -> 2 | N26: -1 | O26: 0 | Q26: 2 | S26: 1 | T26: 0 | U26: 2 | V26: 1 | X26: #REF! | Y26: 0 | Z26: 2 | AA26: 4 | AB26: 1 | AC26: 2 | AE26: #REF!
C27: Result | E27: =F15 -> 0 | F27: =F20 -> 2 | G27: =G20 -> 2 | H27: =MID(I24,1,1)-1 -> -1 | I27: =MID(I24,3,1) -> 1 | M27: {=UNIQUE(TRANSPOSE(G15:G33))} -> 1 | N27: 2 | O27: 2 | P27: -1 | Q27: -1 | R27: 2 | S27: 0 | T27: 0 | V27: 0 | X27: 0 | Y27: 2 | Z27: 0 | AB27: 5 | AC27: 0 | AE27: #REF!
C28: Result | E28: =data!I10 -> 2 | F28: =data!L15 -> 0 | G28: =data!I14 -> 0
A29: =891-746 -> 145 | C29: Result | E29: =F24 -> 4 | H29: =MID(I24,4,1) | I29: =MID(I24,4,1)
C30: Result | E30: =data!L19 -> 1 | F30: =data!L6 -> 0 | G30: =data!O10 -> 5 | N30: 5 | O30: =N30+1 -> 6
C31: Result | E31: =E15 -> 2 | F31: =F15 -> 0 | G31: =E22 -> 0 | H31: =I26+1 -> 1 | N31: 9 | O31: =N31 -> 9
E33: =G13 -> #REF! | F33: =F13 -> 2 | G33: =#REF!+1 -> #REF! | H33: =I27 -> 1 | I33: =I26/I17 -> #DIV/0! | J33: =I29 | K33: =I27 -> 1 | L33: 9 | M33: =M26+I26 -> 2 | N33: =J26-1 -> 1 | O33: =N33-K26 -> 0
E34: =E31/G31 -> #DIV/0! | F34: =F31 -> 0 | G34: =E34*F34 -> #DIV/0! | H34: =I29 | I34: =I29+1 -> 1 | J34: =I27+I17 -> 1 | K34: =I26 -> 0 | M34: =M35 -> -1 | N34: =O35+1 -> 2 | O34: =N35 -> 9
E35: =E23+1 -> 3 | F35: =F23-1 -> -1 | G35: =G23-1 -> -1 | I35: =J34 -> 1 | J35: =K33+1 -> 2 | K35: =J33 | M35: =J33-1 -> -1 | N35: =L33 -> 9 | O35: =K33 -> 1 | W35: 636784
H36: =I29+1 -> 1 | J36: =K33+1 -> 2 | M36: =L33 -> 9 | N36: =K33 -> 1 | O36: =K34 -> 0 | W36: 407636 | AC36: KL
B37: 72 | C37: Result | E37: =data!I12 -> 0 | F37: =data!K15 | G37: =data!I11 | H37: =I27 -> 1 | J37: =K34 -> 0 | K37: =L33-1 -> 8 | M37: =K34 -> 0 | N37: =K33 -> 1 | O37: =L33 -> 9 | AA37: 2 | AB37: 47 | AC37: 51
E38: 3 | F38: 6 | G38: 2 | H38: =I26 -> 0 | J38: =J34+1 -> 2 | K38: =K34 -> 0 | M38: =L33-K33 -> 8 | N38: =J33 | O38: =J34 -> 1
E39: =E37+1 -> 1 | F39: =F37 | G39: =G37+1 -> 1 | I39: =I34+K34 -> 1 | J39: =J34 -> 1 | K39: =K34 -> 0 | M39: =J33 | N39: =CONCATENATE(K33, " 5 to 8 vise") -> 1 5 to 8 vise | O39: 9 or 0 | W39: =W35-W36 -> 229148
A40: =E41 -> 426 | E40: =F15 -> 0 | F40: =E15 -> 2 | G40: =G15+1 -> 2 | I40: =E41 -> 426 | M40: =J33 | N40: =O39 -> 9 or 0 | O40: =K33+1 -> 2 | W40: =W39-AA37 -> 229146 | AA40: =W39-AA37 -> 229146 | AB40: =W40-AB38 -> 229146 | AC40: =W39-AC37 -> 229097
E41: =concatenate(I26:L26)*2 -> 426 | F41: 42 | G41: =E41*F41 -> 17892 | H41: 1 | J41: =I40*H41 -> 426 | L41: B | M41: A/C | N41: C/A | Q41: 3 | R41: 32 | S41: 33 | T41: 321 | V41: 1 | Y41: 3 | Z41: 32 | AA41: 33 | AB41: 321 | AG41: 3 | AH41: 32 | AI41: 33 | AJ41: 321
E42: =CONCATENATE(J26:L26)*2 -> 426 | F42: 22 | G42: =E41*F42 -> 9372 | H42: 2 | I42: =E42 -> 426 | J42: =if(H42*I40>1000,H42*I40-1000, H42*I40) -> 852 | L42: =RIGHT(J41,1) -> 6 | M42: =RIGHT(J42,1) -> 2 | N42: =M42+1 -> 3 | Q42: =R49*2-Q41 -> -67 | R42: =R49*2-R41 -> -96 | S42: =S49*2-S41 -> -99 | T42: =S49*2-T41 -> -387 | Y42: =Z49*2-Y41 -> -67 | Z42: =Z49*2-Z41 -> -96 | AA42: =AA49*2-AA41 -> -99 | AB42: =AA49*2-AB41 -> -387 | AG42: =AH49*2-AG41 -> -67 | AH42: =AH49*2-AH41 -> -96 | AI42: =AI49*2-AI41 -> -99 | AJ42: =AI49*2-AJ41 -> -387
A43: 2 | B43: 5 | E43: KL | H43: 3 | K43: =CONCATENATE(LEFT(J44,1),RIGHT(J44,1),LEFT(J42,1)) -> 468 | L43: =data!O8 -> 3 | M43: =LEFT(J42,1)+1 -> 9 | Q43: =Q46-Q41 -> -3 | R43: =Q49-R41 -> -35 | S43: =T55-S41 -> -354 | T43: =T55-T41 -> -642 | Y43: =Y46-Y41 -> -3 | Z43: =Y49-Z41 -> -35 | AA43: =AB55-AA41 -> -354 | AB43: =AB55-AB41 -> -642 | AG43: =AG46-AG41 -> -3 | AH43: =AG49-AH41 -> -35 | AI43: =AJ55-AI41 -> -33 | AJ43: =AJ55-AJ41 -> -321
D44: target | E44: 703 | F44: 38 | G44: =E44*F44 -> 26714 | J44: =I42*H41 -> 426 | K44: =CONCATENATE(MID(J41,3,1),mid(J41,2,1),left(J45,1)) -> 628 | M44: =LEFT(J45,1) -> 8 | N44: =MID(J45,2,1) -> 5
...

Sheet Sheet28
A1: Process | D1: 6 | E1: 5 | F1: 2 | L1: Middle
A2: 1. last result and current result in the D-F | H2: new number | L2: =E3 -> 0 | M2: =L2-1 -> -1 | N2: =L2+1 -> 1 | P2: 011 become 911
A3: 2. add current values to the last result and check | B3: 76 | D3: 4 | E3: 0 | F3: 0 | H3: 8 | I3: =D1-E1 -> 1 | J3: =I3+F1 -> 3 | L3: 3 | M3: =L3-1 -> 2 | N3: =L3+1 -> 4 | P3: 867 become 857
A4: 3. repeat the same for Last two result diff | B4: 99 | L4: =M2-1 -> -2 | M4: =N2 -> 1 | N4: =L2 -> 0
C5: =B3*B4 -> 7524 | L5: =N2 -> 1 | M5: =M2-1 -> -2 | N5: =L2 -> 0
B6: 58 | H6: 0 | I6: =E3 -> 0 | J6: =I6+J3 -> 3
B7: 78 | H7: =left(D3,1) -> 4 | J7: =L2 -> 0
C8: =B6*B7 -> 4524 | H8: =F1+1 -> 3 | J8: =right(F3,1) -> 0
L9: 126
L10: 465 | O10: sum | P10: avg | Q10: max
A11: A | B11: B | C11: C | H11: =sum(H6:J8) -> 6 | I11: =AVERAGE(H6:J8) -> 1.2 | K11: Last two result diff | L11: =abs(L9-L10) -> 339 | M11: =L11*2 -> 678 | O11: =int(SUM(L11:M11)) -> 1017 | P11: =int(AVERAGE(L11:M11)) -> 508 | Q11: =int(MAX(L11:M11)) -> 678
A12: =data!B7 -> 0 | B12: =data!B8 -> 1 | C12: =Victory!K37 -> 8 | H12: =SUM(H11:I11) -> 7.2
H13: =AVERAGE(H3:J8) -> 2.25 | I13: =SUM(H3:J8) -> 18 | L13: =int(sum(L9:L11)) -> 930 | M13: =INT(AVERAGE(L9:L11)) -> 310 | N13: =int(MAX(L9:L11)) -> 465 | O13: =abs(M11-L9) -> 552 | P13: =abs(O11-L10) -> 552
A14: =data!D7 | B14: =data!A7 -> 0 | P14: a | Q14: b | R14: c
E15: 75802 | G15: Ave | H15: =int(AVERAGE(Victory!P57:R58)) -> 0 | J15: =int(AVERAGE(Victory!X57:Z58)) -> 224347 | L15: =RIGHT(H15,3) -> 0 | N15: =RIGHT(J15,3) -> 347 | Q15: =left(Q11,1) -> 6 | R15: =right(P11,1) -> 8
A16: =data!A8 | B16: =data!D7 | E16: 320 | P16: =right(Q11,1) -> 8 | R16: =LEFT(Q11,1) -> 6
A17: =data!D7 | B17: =data!A8 | D17: ` | G17: Sum | H17: =int(SUM(Victory!P57:R58)) -> 0 | J17: =int(SUM(Victory!X57:Z58)) -> 897390 | L17: =RIGHT(H17,3) -> 0 | N17: =RIGHT(J17,3) -> 390 | R17: =mid(P11,2, 1) -> 0
A18: =data!A7 -> 0 | B18: =data!A8 | Q18: =left(P13,1) -> 5
A19: =data!A8+1 -> 1 | B19: =data!B8 -> 1 | C19: =RIGHT(data!E11,1) -> 1 | G19: Max | H19: =int(SUM(H15:H17)) -> 0 | J19: =int(MAX(Victory!X57:Z58)) -> 395460 | L19: =RIGHT(H19,3) -> 0 | N19: =RIGHT(J19,3) -> 460 | P19: =right(L10,1) -> 5 | Q19: =left(O13,1) -> 5
C20: =data!C6 -> 0 | P20: =mid(P13, 3,1) -> 2 | Q20: =right(L13,1) -> 0
B21: =data!G18 -> 1 | C21: =Victory!F41 -> 42 | Q21: =mid(M13,2, 1) -> 1
C22: =data!H6 -> -3 | L22: AB | P22: =LEFT(L9,1) -> 1
C23: =RIGHT(data!E11,2) -> -1 | D23: A | J23: Note | L23: =RIGHT(L15,2) -> 0 | N23: =RIGHT(N15,2) -> 47
A24: =LEFT(data!E11,1) -> - | B24: =RIGHT(data!E11,1) -> 1 | D24: 7 | E24: 8 | F24: 9 | G24: 8 | H24: 0 | I24: 1 | J24: 6 become 0
A25: =RIGHT(data!E11,3) -> 1-1 | J25: 5 become 8 vise versa | L25: =RIGHT(L17,2) -> 0 | N25: =RIGHT(N17,2) -> 90
A26: =data!F34 -> -2 | B26: =data!G34 -> -2 | J26: 9 become 0 vise versa | L26: =right(L19,2) -> 0
N27: =RIGHT(N19,2) -> 60
A28: =CONCATENATE(" result from ",data!A22, " AND " ,A25) -> result from 9 AND 1-1
B29: AB | C29: =Victory!S118 -> 1 | D29: =CONCATENATE(Victory!M34,Victory!M35) -> -1-1 | E29: =CONCAT(Victory!L42,Victory!M42) -> 62 | F29: =RIGHT(Victory!K43,2) -> 68 | G29: =CONCAT(RIGHT(data!D6,1),LEFT(data!D6,1)) -> 11
B31: BC | C31: =RIGHT(A25,2) -> -1 | D31: =CONCATENATE('Copy of data'!F32:G32) -> 34 | E31: =CONCATENATE(data!D13,data!D12) -> -11 | F31: =CONCAT(RIGHT(D31,1),LEFT(D31,1)) -> 43 | G31: =CONCAT(Victory!S119,Victory!S118) -> 1.333333333333331
B33: AC | C33: =CONCATENATE(A24,B24) -> -1 | D33: =CONCATENATE(data!D13,data!D12) -> -11 | E33: =data!D6 -> 1
B36: ='Copy of Copy of data'!A9 -> AB/AC | C36: ='Copy of Copy of data'!B9 -> Result
B37: ='Copy of Copy of data'!A10 -> 60 | C37: ='Copy of Copy of data'!B10 -> 880
B38: ='Copy of Copy of data'!A11 -> 0 | C38: ='Copy of Copy of data'!B11 -> 83 | M38: =K38+1 -> 1
B39: ='Copy of Copy of data'!A12 | C39: =CONCATENATE(LEFT(C38,1)+1,MID(C38,2,1),MID(C38,2,1)-RIGHT(C38,1)) -> 930 | M39: =K39+1 -> 1
B40: ='Copy of Copy of data'!A13 -> BC/AB/AC | C40: ='Copy of Copy of data'!B13
B41: ='Copy of Copy of data'!A14 -> 00 | C41: ='Copy of Copy of data'!B14
B42: ='Copy of Copy of data'!A15 -> 80 | C42: ='Copy of Copy of data'!B15
B43: ='Copy of Copy of data'!A16 -> 1 | C43: =data!C18
N46: sum | O46: avg | P46: max
...

Sheet Sheet27
C1: Mon | D1: Tue | E1: Wed | F1: Thu | G1: Fri | H1: Sat | I1: Sun | N1: Victory Ref | O1: A | P1: B | Q1: C | R1: Result
K2: 14 | L2: 1 | M2: 15 | N2: =CONCATENATE(Victory!AF90:AF92) -> 01-1 | O2: =LEFT(K2,1) -> 1 | P2: =MID(Victory!Y104,3,1) -> 9 | Q2: =MID(Victory!Y104,3,1) -> 9 | R2: 100 | S2: 0.54166667
A3: Odd | G3: 13 | J3: =CONCAT(A3,F1) -> OddThu | K3: 7 | L3: 6 | M3: 1 | N3: =CONCATENATE(Victory!AG90:AG91) -> 4-1 | O3: =MID(Victory!V104,2,1) -> 0 | P3: =MID(Victory!V104,4,1) -> 8 | Q3: =MID(Victory!W105,3,1) -> 8
A4: Even | G4: 31 | K4: 0 | L4: 4 | M4: 16 | N4: =CONCATENATE(Victory!AG77:AG78) -> 1080 | O4: =LEFT(Victory!T101,1) -> 2 | P4: =Victory!S118 -> 1
K5: 0 | L5: 8 | M5: 2 | O5: =data!A7 -> 0 | P5: =data!A9+1 -> 1 | Q5: =M5 -> 2
